
[2024-05-23 15:50:17,455][dinov2][INFO] - using MLP layer as FFN
Using cache found in /Users/loris/.cache/torch/hub/facebookresearch_dinov2_main
/Users/loris/.cache/torch/hub/facebookresearch_dinov2_main/dinov2/layers/swiglu_ffn.py:51: UserWarning: xFormers is not available (SwiGLU)
  warnings.warn("xFormers is not available (SwiGLU)")
/Users/loris/.cache/torch/hub/facebookresearch_dinov2_main/dinov2/layers/attention.py:33: UserWarning: xFormers is not available (Attention)
  warnings.warn("xFormers is not available (Attention)")
/Users/loris/.cache/torch/hub/facebookresearch_dinov2_main/dinov2/layers/block.py:40: UserWarning: xFormers is not available (Block)
  warnings.warn("xFormers is not available (Block)")
Error executing job with overrides: []
Traceback (most recent call last):
  File "/Library/Frameworks/Python.framework/Versions/3.12/lib/python3.12/site-packages/hydra/_internal/instantiate/_instantiate2.py", line 92, in _call_target
    return _target_(*args, **kwargs)
           ^^^^^^^^^^^^^^^^^^^^^^^^^
  File "/Users/loris/X/MODAL/challenge-modal/data/datamodule.py", line 21, in __init__
    self.dataset1 = ImageFolder(train_dataset_path, transform=train_transform1)
                    ^^^^^^^^^^^^^^^^^^^^^^^^^^^^^^^^^^^^^^^^^^^^^^^^^^^^^^^^^^^
  File "/Library/Frameworks/Python.framework/Versions/3.12/lib/python3.12/site-packages/torchvision/datasets/folder.py", line 309, in __init__
    super().__init__(
  File "/Library/Frameworks/Python.framework/Versions/3.12/lib/python3.12/site-packages/torchvision/datasets/folder.py", line 144, in __init__
    classes, class_to_idx = self.find_classes(self.root)
                            ^^^^^^^^^^^^^^^^^^^^^^^^^^^^
  File "/Library/Frameworks/Python.framework/Versions/3.12/lib/python3.12/site-packages/torchvision/datasets/folder.py", line 218, in find_classes
    return find_classes(directory)
           ^^^^^^^^^^^^^^^^^^^^^^^
  File "/Library/Frameworks/Python.framework/Versions/3.12/lib/python3.12/site-packages/torchvision/datasets/folder.py", line 40, in find_classes
    classes = sorted(entry.name for entry in os.scandir(directory) if entry.is_dir())
                                             ^^^^^^^^^^^^^^^^^^^^^
FileNotFoundError: [Errno 2] No such file or directory: '/Users/loris/X/MODAL/challenge-modal/dataset/train/first_week_dataset'
The above exception was the direct cause of the following exception:
Traceback (most recent call last):
  File "/Users/loris/X/MODAL/challenge-modal/train.py", line 97, in <module>
    train()
  File "/Library/Frameworks/Python.framework/Versions/3.12/lib/python3.12/site-packages/hydra/main.py", line 94, in decorated_main
    _run_hydra(
  File "/Library/Frameworks/Python.framework/Versions/3.12/lib/python3.12/site-packages/hydra/_internal/utils.py", line 394, in _run_hydra
    _run_app(
  File "/Library/Frameworks/Python.framework/Versions/3.12/lib/python3.12/site-packages/hydra/_internal/utils.py", line 457, in _run_app
    run_and_report(
  File "/Library/Frameworks/Python.framework/Versions/3.12/lib/python3.12/site-packages/hydra/_internal/utils.py", line 223, in run_and_report
    raise ex
  File "/Library/Frameworks/Python.framework/Versions/3.12/lib/python3.12/site-packages/hydra/_internal/utils.py", line 220, in run_and_report
    return func()
           ^^^^^^
  File "/Library/Frameworks/Python.framework/Versions/3.12/lib/python3.12/site-packages/hydra/_internal/utils.py", line 458, in <lambda>
    lambda: hydra.run(
            ^^^^^^^^^^
  File "/Library/Frameworks/Python.framework/Versions/3.12/lib/python3.12/site-packages/hydra/_internal/hydra.py", line 132, in run
    _ = ret.return_value
        ^^^^^^^^^^^^^^^^
  File "/Library/Frameworks/Python.framework/Versions/3.12/lib/python3.12/site-packages/hydra/core/utils.py", line 260, in return_value
    raise self._return_value
  File "/Library/Frameworks/Python.framework/Versions/3.12/lib/python3.12/site-packages/hydra/core/utils.py", line 186, in run_job
    ret.return_value = task_function(task_cfg)
                       ^^^^^^^^^^^^^^^^^^^^^^^
  File "/Users/loris/X/MODAL/challenge-modal/train.py", line 15, in train
    datamodule = hydra.utils.instantiate(cfg.datamodule) #objet de classe DataModule avec tous les param√®tres de config
                 ^^^^^^^^^^^^^^^^^^^^^^^^^^^^^^^^^^^^^^^
  File "/Library/Frameworks/Python.framework/Versions/3.12/lib/python3.12/site-packages/hydra/_internal/instantiate/_instantiate2.py", line 226, in instantiate
    return instantiate_node(
           ^^^^^^^^^^^^^^^^^
  File "/Library/Frameworks/Python.framework/Versions/3.12/lib/python3.12/site-packages/hydra/_internal/instantiate/_instantiate2.py", line 347, in instantiate_node
    return _call_target(_target_, partial, args, kwargs, full_key)
           ^^^^^^^^^^^^^^^^^^^^^^^^^^^^^^^^^^^^^^^^^^^^^^^^^^^^^^^
  File "/Library/Frameworks/Python.framework/Versions/3.12/lib/python3.12/site-packages/hydra/_internal/instantiate/_instantiate2.py", line 97, in _call_target
    raise InstantiationException(msg) from e
hydra.errors.InstantiationException: Error in call to target 'data.datamodule.DataModule':
FileNotFoundError(2, 'No such file or directory')
full_key: datamodule